{"name": "test_criar_um_usuário_com_credenciais_válidas", "status": "failed", "statusDetails": {"message": "AssertionError: ❌ Erro ao criar usuário: {\"code\":\"1204\",\"message\":\"User exists!\"}\nassert 406 == 201\n +  where 406 = <Response [406]>.status_code\n +    where <Response [406]> = pytest.response", "trace": "fixturefunc = <function verify_user_creation at 0x108fd2520>, request = <FixtureRequest for <Function test_criar_um_usuário_com_credenciais_válidas>>, kwargs = {}\n\n    def call_fixture_func(\n        fixturefunc: _FixtureFunc[FixtureValue], request: FixtureRequest, kwargs\n    ) -> FixtureValue:\n        if is_generator(fixturefunc):\n            fixturefunc = cast(\n                Callable[..., Generator[FixtureValue, None, None]], fixturefunc\n            )\n            generator = fixturefunc(**kwargs)\n            try:\n                fixture_result = next(generator)\n            except StopIteration:\n                raise ValueError(f\"{request.fixturename} did not yield a value\") from None\n            finalizer = functools.partial(_teardown_yield_fixture, fixturefunc, generator)\n            request.addfinalizer(finalizer)\n        else:\n            fixturefunc = cast(Callable[..., FixtureValue], fixturefunc)\n>           fixture_result = fixturefunc(**kwargs)\n\n.venv/lib/python3.13/site-packages/_pytest/fixtures.py:898: \n_ _ _ _ _ _ _ _ _ _ _ _ _ _ _ _ _ _ _ _ _ _ _ _ _ _ _ _ _ _ _ _ _ _ _ _ _ _ _ _ _ _ _ _ _ _ _ _ _ _ _ _ _ _ _ _ _ _ _ _ _ _ _ _ _ _ _ _ _ _ _ _ _ _ _ _ _ _ _ _ _ \n\n    @then(\"a API deve retornar um status 201\")\n    def verify_user_creation():\n        \"\"\"Verifica se o usuário foi criado com sucesso\"\"\"\n>       assert pytest.response.status_code == 201, f\"❌ Erro ao criar usuário: {pytest.response.text}\"\nE       AssertionError: ❌ Erro ao criar usuário: {\"code\":\"1204\",\"message\":\"User exists!\"}\nE       assert 406 == 201\nE        +  where 406 = <Response [406]>.status_code\nE        +    where <Response [406]> = pytest.response\n\ntests/api/test_create_user.py:33: AssertionError"}, "description": "/Users/bi003709/Documents/Projeto-desafio/features/api_create_user.feature: Criar um usuário com credenciais válidas", "start": 1746632084742, "stop": 1746632085332, "uuid": "644fb7e7-1890-4f65-a754-1ab4c44bdb30", "historyId": "a7574963e73b147341298284211deff8", "testCaseId": "a7574963e73b147341298284211deff8", "fullName": "tests.api.test_create_user#test_criar_um_usuário_com_credenciais_válidas", "labels": [{"name": "parentSuite", "value": "tests.api"}, {"name": "suite", "value": "test_create_user"}, {"name": "host", "value": "rec-a-011826"}, {"name": "thread", "value": "60199-MainThread"}, {"name": "framework", "value": "pytest"}, {"name": "language", "value": "cpython3"}, {"name": "package", "value": "tests.api.test_create_user"}]}